{"uuid": "6c98a677-43e7-44c1-a32e-4cda21eee409", "children": ["5240b586-4833-449a-9cbc-9b3e86e20397"], "befores": [{"name": "driver", "status": "broken", "statusDetails": {"message": "selenium.common.exceptions.SessionNotCreatedException: Message: session not created\nfrom disconnected: unable to connect to renderer\nStacktrace:\n#0 0x559500f78ffa <unknown>\n#1 0x559500a37970 <unknown>\n#2 0x559500a77711 <unknown>\n#3 0x559500a7229a <unknown>\n#4 0x559500a6d18f <unknown>\n#5 0x559500abdbd9 <unknown>\n#6 0x559500abd106 <unknown>\n#7 0x559500aaf063 <unknown>\n#8 0x559500a7b328 <unknown>\n#9 0x559500a7c491 <unknown>\n#10 0x559500f4042b <unknown>\n#11 0x559500f442ec <unknown>\n#12 0x559500f27a22 <unknown>\n#13 0x559500f44e64 <unknown>\n#14 0x559500f0bbef <unknown>\n#15 0x559500f67558 <unknown>\n#16 0x559500f67736 <unknown>\n#17 0x559500f77e76 <unknown>\n#18 0x7f27c509caa4 <unknown>\n#19 0x7f27c5129c3c <unknown>\n\n", "trace": "  File \"/home/runner/work/QATEST/QATEST/venv/lib/python3.11/site-packages/pluggy/_callers.py\", line 167, in _multicall\n    teardown.throw(outcome._exception)\n  File \"/home/runner/work/QATEST/QATEST/venv/lib/python3.11/site-packages/_pytest/setuponly.py\", line 36, in pytest_fixture_setup\n    return (yield)\n            ^^^^^\n  File \"/home/runner/work/QATEST/QATEST/venv/lib/python3.11/site-packages/pluggy/_callers.py\", line 103, in _multicall\n    res = hook_impl.function(*args)\n          ^^^^^^^^^^^^^^^^^^^^^^^^^\n  File \"/home/runner/work/QATEST/QATEST/venv/lib/python3.11/site-packages/_pytest/fixtures.py\", line 1140, in pytest_fixture_setup\n    result = call_fixture_func(fixturefunc, request, kwargs)\n             ^^^^^^^^^^^^^^^^^^^^^^^^^^^^^^^^^^^^^^^^^^^^^^^\n  File \"/home/runner/work/QATEST/QATEST/venv/lib/python3.11/site-packages/_pytest/fixtures.py\", line 891, in call_fixture_func\n    fixture_result = next(generator)\n                     ^^^^^^^^^^^^^^^\n  File \"/home/runner/work/QATEST/QATEST/src/tests/ui_tests/conftest.py\", line 23, in driver\n    driver = webdriver.Chrome(service=service_obj,options=chrome_options)\n             ^^^^^^^^^^^^^^^^^^^^^^^^^^^^^^^^^^^^^^^^^^^^^^^^^^^^^^^^^^^^\n  File \"/home/runner/work/QATEST/QATEST/venv/lib/python3.11/site-packages/selenium/webdriver/chrome/webdriver.py\", line 45, in __init__\n    super().__init__(\n  File \"/home/runner/work/QATEST/QATEST/venv/lib/python3.11/site-packages/selenium/webdriver/chromium/webdriver.py\", line 66, in __init__\n    super().__init__(command_executor=executor, options=options)\n  File \"/home/runner/work/QATEST/QATEST/venv/lib/python3.11/site-packages/selenium/webdriver/remote/webdriver.py\", line 241, in __init__\n    self.start_session(capabilities)\n  File \"/home/runner/work/QATEST/QATEST/venv/lib/python3.11/site-packages/selenium/webdriver/remote/webdriver.py\", line 329, in start_session\n    response = self.execute(Command.NEW_SESSION, caps)[\"value\"]\n               ^^^^^^^^^^^^^^^^^^^^^^^^^^^^^^^^^^^^^^^\n  File \"/home/runner/work/QATEST/QATEST/venv/lib/python3.11/site-packages/selenium/webdriver/remote/webdriver.py\", line 384, in execute\n    self.error_handler.check_response(response)\n  File \"/home/runner/work/QATEST/QATEST/venv/lib/python3.11/site-packages/selenium/webdriver/remote/errorhandler.py\", line 232, in check_response\n    raise exception_class(message, screen, stacktrace)\n"}, "start": 1743197356290, "stop": 1743197356486}], "start": 1743197356290, "stop": 1743197356515}